Workbook

Sheet README
A1: SA-CCR EAD Calculator - Standardised Approach for Counterparty Credit Risk
B3: Source
B4: BIS d279, 'Standardised approach for measuring counterparty credit risk exposures', March 2014 (rev. Apr 2014). bis.org/publ/bcbs279.htm
B6: Formula
B7: EAD = alpha x (RC + PFE), alpha = 1.4
B8: RC unmargined = max(V - C, 0)
B9: RC margined = max(V - C, TH + MTA - NICA, 0)
B10: PFE = Multiplier x AddOn_aggregate
B11: Multiplier = min[1, Floor + (1-Floor) x exp((V-C) / (2 x (1-Floor) x AddOn_aggregate))], Floor = 5%
B12: AddOn_aggregate = sum of AddOn by asset class (IR, FX, Credit, Equity, Commodity)
B14: Trade-level waterfall
B15: 1. Adjusted notional d: notional x SD for IR/Credit, SD = [exp(-0.05S) - exp(-0.05E)] / 0.05; notional directly for FX/Equity/Commodity
B16: 2. Supervisory delta: +/-1 linear; Black-Scholes via NORMSDIST(d1) for options
... B37: - Basis/volatility add-ons and BA-CVA out of scope
A40: BA-CVA extension (Reduced BA-CVA, no hedge recognition)
A41: Source: Clarus Financial Technology 'FRTB - Basic Approach for CVA'; OSFI CAR 2026 Ch. 8 CVA Risk
A42: SCVA_c = (1/alpha) x RW_c x sum_NS(M_NS x EAD_NS x DF_NS), alpha = 1.4
A43: DF_NS = (1-EXP(-0.05*M_NS))/(0.05*M_NS)
A44: K_reduced = SQRT[(rho x sum SCVA_c)^2 + (1-rho^2) x sum(SCVA_c^2)], rho = 0.5
A45: BA-CVA capital charge = discount_scalar x K_reduced, discount_scalar = 0.65
A46: M_NS is a notional-weighted average trade maturity per netting set, a documented proxy for Basel's cashflow-weighted effective maturity (no cashflow schedule in the sample data)
A47: EAD_NS is each netting set's actual margin-status EAD from the Summary sheet (NS-A unmargined, NS-B margined)
A48: Counterparty sector/credit quality (BACVA_Counterparties sheet) are new, illustrative assumptions
A49: Sheets: BACVA_Params, BACVA_Counterparties, BACVA_Calc, BACVA_Summary

Sheet Supervisory_Params
A1: Supervisory Parameters (BIS d279, Annex 4) - all editable inputs (blue)
A3: Supervisory Factors (SF) - Annex 4, Table 2
A4: Asset Class | B4: Sub-Category | C4: Key | D4: SF | E4: Note
A5: IR | B5: NA | C5: =A5&"|"&B5 | D5: 0.005 | E5: Flat factor, all currencies/tenors
A6: FX | B6: NA | C6: =A6&"|"&B6 | D6: 0.04 | E6: Flat factor, all currency pairs
A7: Credit | B7: BBB | C7: =A7&"|"&B7 | D7: 0.0054 | E7: Single-name, investment grade (BBB)
A8: Credit | B8: IG_Index | C8: =A8&"|"&B8 | D8: 0.0038 | E8: Credit index, investment grade
A9: Credit | B9: SubIG_Index | C9: =A9&"|"&B9 | D9: 0.0106 | E9: Credit index, sub-investment grade
A10: Equity | B10: SingleName | C10: =A10&"|"&B10 | D10: 0.32 | E10: Single-name equity
A11: Equity | B11: Index | C11: =A11&"|"&B11 | D11: 0.2 | E11: Equity index
A12: Commodity | B12: Oil_Gas | C12: =A12&"|"&B12 | D12: 0.18 | E12: Oil/gas
A13: Commodity | B13: Metal | C13: =A13&"|"&B13 | D13: 0.18 | E13: Metal
A15: Regulatory Constants & Correlations
A16: Parameter | B16: Value | E16: Note
A17: Alpha (regulatory multiplier) | B17: 1.4 | E17: BIS d279 para 121
A18: Multiplier floor | B18: 0.05 | E18: BIS d279 para 149
A19: IR cross-bucket correlation, adjacent buckets (1-2, 2-3) | B19: 0.7 | E19: Applied as 2x = 1.40x cross term
A20: IR cross-bucket correlation, buckets 1-3 | B20: 0.3 | E20: Applied as 2x = 0.60x cross term
A21: Correlation (rho), single-name credit/equity | B21: 0.5 | E21: BIS d279 para 188 (credit), 190 (equity)
A22: Correlation (rho), credit/equity index | B22: 0.8 | E22: Index constituents are more correlated
A23: Correlation (rho), commodity (all types) | B23: 0.4 | E23: BIS d279 para 192
A24: MPOR floor, standard netting set (business days) | B24: 10 | E24: BIS d279 para 164; 5d cleared / 20d large-or-illiquid not modeled
A25: Unmargined maturity floor (business days) | B25: 10 | E25: BIS d279 para 159
A26: Business days per year | B26: 250 | E26: Standard convention
A28: MF, margined (standard MPOR floor) = 1.5 x sqrt(MPOR/1yr) | B28: =1.5*SQRT(Supervisory_Params!$B$24/Supervisory_Params!$B$26)

Sheet Trade_Inputs
A1: Trade Inputs - illustrative 18-trade sample portfolio (all cells blue = editable)
A3: Trade ID | B3: Netting Set | C3: Asset Class | D3: Hedging Set | E3: Position | F3: Style | G3: Opt Type | H3: Notional (USD) | I3: Start S (yrs) | J3: Maturity M (yrs) | K3: Underlying Price | L3: Strike | M3: Vol (ann.) | N3: MTM (USD) | O3: Sub-Category
A4: IRS-USD-5Y | B4: NS-A | C4: IR | D4: USD | E4: Long | F4: Linear | G4: NA | H4: 50000000 | I4: 0 | J4: 5 | N4: 350000 | O4: NA
A5: IRS-USD-2Y | B5: NS-A | C5: IR | D5: USD | E5: Short | F5: Linear | G5: NA | H5: 30000000 | I5: 0 | J5: 2 | N5: -120000 | O5: NA
A6: IRS-EUR-7Y | B6: NS-A | C6: IR | D6: EUR | E6: Long | F6: Linear | G6: NA | H6: 20000000 | I6: 0 | J6: 7 | N6: 210000 | O6: NA
A7: FXFWD-EURUSD-1Y | B7: NS-A | C7: FX | D7: EURUSD | E7: Long | F7: Linear | G7: NA | H7: 15000000 | I7: 0 | J7: 1 | N7: 45000 | O7: NA
A8: FXFWD-GBPUSD-6M | B8: NS-A | C8: FX | D8: GBPUSD | E8: Short | F8: Linear | G8: NA | H8: 10000000 | I8: 0 | J8: 0.5 | N8: -30000 | O8: NA
A9: FXOPT-USDJPY-9M | B9: NS-A | C9: FX | D9: USDJPY | E9: Long | F9: Option | G9: Call | H9: 8000000 | I9: 0 | J9: 0.75 | K9: 150 | L9: 152 | M9: 0.1 | N9: 60000 | O9: NA
A10: CDS-SN-BBB-3Y | B10: NS-A | C10: Credit | D10: Corp_XYZ | E10: Long | F10: Linear | G10: NA | H10: 12000000 | I10: 0 | J10: 3 | N10: -25000 | O10: BBB
A11: CDS-IDX-IG-5Y | B11: NS-A | C11: Credit | D11: CDX_IG | E11: Short | F11: Linear | G11: NA | H11: 25000000 | I11: 0 | J11: 5 | N11: 40000 | O11: IG_Index
A12: EQSWAP-SN-XYZ-2Y | B12: NS-A | C12: Equity | D12: Equity_XYZ | E12: Long | F12: Linear | G12: NA | H12: 6000000 | I12: 0 | J12: 2 | N12: 15000 | O12: SingleName
A13: EQOPT-IDX-SPX-1Y | B13: NS-A | C13: Equity | D13: Equity_SPX | E13: Long | F13: Option | G13: Put | H13: 10000000 | I13: 0 | J13: 1 | K13: 5000 | L13: 4800 | M13: 0.18 | N13: -80000 | O13: Index
A14: COMDTY-OIL-1Y | B14: NS-A | C14: Commodity | D14: Oil_Gas | E14: Long | F14: Linear | G14: NA | H14: 5000000 | I14: 0 | J14: 1 | N14: 20000 | O14: Oil_Gas
A15: COMDTY-GOLD-2Y | B15: NS-A | C15: Commodity | D15: Metal | E15: Short | F15: Linear | G15: NA | H15: 4000000 | I15: 0 | J15: 2 | N15: -10000 | O15: Metal
A16: IRS-USD-10Y | B16: NS-B | C16: IR | D16: USD | E16: Long | F16: Linear | G16: NA | H16: 40000000 | I16: 0 | J16: 10 | N16: 500000 | O16: NA
A17: IRS-USD-3Y | B17: NS-B | C17: IR | D17: USD | E17: Short | F17: Linear | G17: NA | H17: 25000000 | I17: 0 | J17: 3 | N17: -90000 | O17: NA
A18: FXFWD-EURUSD-2Y | B18: NS-B | C18: FX | D18: EURUSD | E18: Long | F18: Linear | G18: NA | H18: 18000000 | I18: 0 | J18: 2 | N18: 55000 | O18: NA
A19: FXFWD-USDJPY-1Y | B19: NS-B | C19: FX | D19: USDJPY | E19: Short | F19: Linear | G19: NA | H19: 12000000 | I19: 0 | J19: 1 | N19: -40000 | O19: NA
A20: CDS-IDX-SUBIG-4Y | B20: NS-B | C20: Credit | D20: CDX_HY | E20: Long | F20: Linear | G20: NA | H20: 15000000 | I20: 0 | J20: 4 | N20: -35000 | O20: SubIG_Index
A21: EQSWAP-IDX-SPX-3Y | B21: NS-B | C21: Equity | D21: Equity_SPX | E21: Long | F21: Linear | G21: NA | H21: 20000000 | I21: 0 | J21: 3 | N21: 80000 | O21: Index
A23: Legend:
A24: Blue fill (light blue) = Netting Set A trades (CORP-001, uncollateralised)
A25: Orange fill = Netting Set B trades (BANK-001, collateralised under two-way CSA)
A26: All values in blue font are editable inputs; nothing on this sheet is a formula.

Sheet Calc_Engine
A1: Calc Engine - per-trade SA-CCR waterfall (green = link to Trade_Inputs, black = formula)
A3: Trade ID | B3: Netting Set | C3: Asset Class | D3: Hedging Set | E3: Position | F3: Style | G3: Opt Type | H3: Maturity M (yrs) | I3: Sup. Duration SD | J3: Adj. Notional d | K3: d1 (options) | L3: Sup. Delta | M3: MF Unmargined | N3: MF Margined | O3: EffNotional Unmarg. | P3: EffNotional Marg. | Q3: SF | R3: Corr (rho)
A4: =Trade_Inputs!A4 | B4: =Trade_Inputs!B4 | C4: =Trade_Inputs!C4 | D4: =Trade_Inputs!D4 | E4: =Trade_Inputs!E4 | F4: =Trade_Inputs!F4 | G4: =Trade_Inputs!G4 | H4: =Trade_Inputs!J4 | I4: =IF(OR(C4="IR",C4="Credit"),(EXP(-0.05*Trade_Inputs!I4)-EXP(-0.05*Trade_Inputs!J4))/0.05,"") | J4: =IF(OR(C4="IR",C4="Credit"),Trade_Inputs!H4*I4,Trade_Inputs!H4) | K4: =IF(F4="Option",(LN(Trade_Inputs!K4/Trade_Inputs!L4)+0.5*Trade_Inputs!M4^2*Trade_Inputs!J4)/(Trade_Inputs!M4*SQRT(Trade_Inputs!J4)),"") | L4: =IF(F4="Linear",IF(E4="Long",1,-1),IF(AND(F4="Option",G4="Call"),IF(E4="Long",NORMSDIST(K4),-NORMSDIST(K4)),IF(AND(F4="Option",G4="Put"),IF(E4="Long",-NORMSDIST(-K4),NORMSDIST(-K4)),""))) | M4: =SQRT(MIN(MAX(H4,Supervisory_Params!$B$25/Supervisory_Params!$B$26),1)) | N4: =Supervisory_Params!$B$28 | O4: =L4*J4*M4 | P4: =L4*J4*N4 | Q4: =INDEX(Supervisory_Params!$D$5:$D$13,MATCH(C4&"|"&Trade_Inputs!O4,Supervisory_Params!$C$5:$C$13,0)) | R4: =IF(OR(C4="IR",C4="FX"),0,IF(C4="Commodity",Supervisory_Params!$B$23,IF(ISNUMBER(SEARCH("Index",Trade_Inputs!O4)),Supervisory_Params!$B$22,Supervisory_Params!$B$21)))
A5: =Trade_Inputs!A5 | B5: =Trade_Inputs!B5 | C5: =Trade_Inputs!C5 | D5: =Trade_Inputs!D5 | E5: =Trade_Inputs!E5 | F5: =Trade_Inputs!F5 | G5: =Trade_Inputs!G5 | H5: =Trade_Inputs!J5 | I5: =IF(OR(C5="IR",C5="Credit"),(EXP(-0.05*Trade_Inputs!I5)-EXP(-0.05*Trade_Inputs!J5))/0.05,"") | J5: =IF(OR(C5="IR",C5="Credit"),Trade_Inputs!H5*I5,Trade_Inputs!H5) | K5: =IF(F5="Option",(LN(Trade_Inputs!K5/Trade_Inputs!L5)+0.5*Trade_Inputs!M5^2*Trade_Inputs!J5)/(Trade_Inputs!M5*SQRT(Trade_Inputs!J5)),"") | L5: =IF(F5="Linear",IF(E5="Long",1,-1),IF(AND(F5="Option",G5="Call"),IF(E5="Long",NORMSDIST(K5),-NORMSDIST(K5)),IF(AND(F5="Option",G5="Put"),IF(E5="Long",-NORMSDIST(-K5),NORMSDIST(-K5)),""))) | M5: =SQRT(MIN(MAX(H5,Supervisory_Params!$B$25/Supervisory_Params!$B$26),1)) | N5: =Supervisory_Params!$B$28 | O5: =L5*J5*M5 | P5: =L5*J5*N5 | Q5: =INDEX(Supervisory_Params!$D$5:$D$13,MATCH(C5&"|"&Trade_Inputs!O5,Supervisory_Params!$C$5:$C$13,0)) | R5: =IF(OR(C5="IR",C5="FX"),0,IF(C5="Commodity",Supervisory_Params!$B$23,IF(ISNUMBER(SEARCH("Index",Trade_Inputs!O5)),Supervisory_Params!$B$22,Supervisory_Params!$B$21)))
A6: =Trade_Inputs!A6 | B6: =Trade_Inputs!B6 | C6: =Trade_Inputs!C6 | D6: =Trade_Inputs!D6 | E6: =Trade_Inputs!E6 | F6: =Trade_Inputs!F6 | G6: =Trade_Inputs!G6 | H6: =Trade_Inputs!J6 | I6: =IF(OR(C6="IR",C6="Credit"),(EXP(-0.05*Trade_Inputs!I6)-EXP(-0.05*Trade_Inputs!J6))/0.05,"") | J6: =IF(OR(C6="IR",C6="Credit"),Trade_Inputs!H6*I6,Trade_Inputs!H6) | K6: =IF(F6="Option",(LN(Trade_Inputs!K6/Trade_Inputs!L6)+0.5*Trade_Inputs!M6^2*Trade_Inputs!J6)/(Trade_Inputs!M6*SQRT(Trade_Inputs!J6)),"") | L6: =IF(F6="Linear",IF(E6="Long",1,-1),IF(AND(F6="Option",G6="Call"),IF(E6="Long",NORMSDIST(K6),-NORMSDIST(K6)),IF(AND(F6="Option",G6="Put"),IF(E6="Long",-NORMSDIST(-K6),NORMSDIST(-K6)),""))) | M6: =SQRT(MIN(MAX(H6,Supervisory_Params!$B$25/Supervisory_Params!$B$26),1)) | N6: =Supervisory_Params!$B$28 | O6: =L6*J6*M6 | P6: =L6*J6*N6 | Q6: =INDEX(Supervisory_Params!$D$5:$D$13,MATCH(C6&"|"&Trade_Inputs!O6,Supervisory_Params!$C$5:$C$13,0)) | R6: =IF(OR(C6="IR",C6="FX"),0,IF(C6="Commodity",Supervisory_Params!$B$23,IF(ISNUMBER(SEARCH("Index",Trade_Inputs!O6)),Supervisory_Params!$B$22,Supervisory_Params!$B$21)))
A7: =Trade_Inputs!A7 | B7: =Trade_Inputs!B7 | C7: =Trade_Inputs!C7 | D7: =Trade_Inputs!D7 | E7: =Trade_Inputs!E7 | F7: =Trade_Inputs!F7 | G7: =Trade_Inputs!G7 | H7: =Trade_Inputs!J7 | I7: =IF(OR(C7="IR",C7="Credit"),(EXP(-0.05*Trade_Inputs!I7)-EXP(-0.05*Trade_Inputs!J7))/0.05,"") | J7: =IF(OR(C7="IR",C7="Credit"),Trade_Inputs!H7*I7,Trade_Inputs!H7) | K7: =IF(F7="Option",(LN(Trade_Inputs!K7/Trade_Inputs!L7)+0.5*Trade_Inputs!M7^2*Trade_Inputs!J7)/(Trade_Inputs!M7*SQRT(Trade_Inputs!J7)),"") | L7: =IF(F7="Linear",IF(E7="Long",1,-1),IF(AND(F7="Option",G7="Call"),IF(E7="Long",NORMSDIST(K7),-NORMSDIST(K7)),IF(AND(F7="Option",G7="Put"),IF(E7="Long",-NORMSDIST(-K7),NORMSDIST(-K7)),""))) | M7: =SQRT(MIN(MAX(H7,Supervisory_Params!$B$25/Supervisory_Params!$B$26),1)) | N7: =Supervisory_Params!$B$28 | O7: =L7*J7*M7 | P7: =L7*J7*N7 | Q7: =INDEX(Supervisory_Params!$D$5:$D$13,MATCH(C7&"|"&Trade_Inputs!O7,Supervisory_Params!$C$5:$C$13,0)) | R7: =IF(OR(C7="IR",C7="FX"),0,IF(C7="Commodity",Supervisory_Params!$B$23,IF(ISNUMBER(SEARCH("Index",Trade_Inputs!O7)),Supervisory_Params!$B$22,Supervisory_Params!$B$21)))
A8: =Trade_Inputs!A8 | B8: =Trade_Inputs!B8 | C8: =Trade_Inputs!C8 | D8: =Trade_Inputs!D8 | E8: =Trade_Inputs!E8 | F8: =Trade_Inputs!F8 | G8: =Trade_Inputs!G8 | H8: =Trade_Inputs!J8 | I8: =IF(OR(C8="IR",C8="Credit"),(EXP(-0.05*Trade_Inputs!I8)-EXP(-0.05*Trade_Inputs!J8))/0.05,"") | J8: =IF(OR(C8="IR",C8="Credit"),Trade_Inputs!H8*I8,Trade_Inputs!H8) | K8: =IF(F8="Option",(LN(Trade_Inputs!K8/Trade_Inputs!L8)+0.5*Trade_Inputs!M8^2*Trade_Inputs!J8)/(Trade_Inputs!M8*SQRT(Trade_Inputs!J8)),"") | L8: =IF(F8="Linear",IF(E8="Long",1,-1),IF(AND(F8="Option",G8="Call"),IF(E8="Long",NORMSDIST(K8),-NORMSDIST(K8)),IF(AND(F8="Option",G8="Put"),IF(E8="Long",-NORMSDIST(-K8),NORMSDIST(-K8)),""))) | M8: =SQRT(MIN(MAX(H8,Supervisory_Params!$B$25/Supervisory_Params!$B$26),1)) | N8: =Supervisory_Params!$B$28 | O8: =L8*J8*M8 | P8: =L8*J8*N8 | Q8: =INDEX(Supervisory_Params!$D$5:$D$13,MATCH(C8&"|"&Trade_Inputs!O8,Supervisory_Params!$C$5:$C$13,0)) | R8: =IF(OR(C8="IR",C8="FX"),0,IF(C8="Commodity",Supervisory_Params!$B$23,IF(ISNUMBER(SEARCH("Index",Trade_Inputs!O8)),Supervisory_Params!$B$22,Supervisory_Params!$B$21)))
A9: =Trade_Inputs!A9 | B9: =Trade_Inputs!B9 | C9: =Trade_Inputs!C9 | D9: =Trade_Inputs!D9 | E9: =Trade_Inputs!E9 | F9: =Trade_Inputs!F9 | G9: =Trade_Inputs!G9 | H9: =Trade_Inputs!J9 | I9: =IF(OR(C9="IR",C9="Credit"),(EXP(-0.05*Trade_Inputs!I9)-EXP(-0.05*Trade_Inputs!J9))/0.05,"") | J9: =IF(OR(C9="IR",C9="Credit"),Trade_Inputs!H9*I9,Trade_Inputs!H9) | K9: =IF(F9="Option",(LN(Trade_Inputs!K9/Trade_Inputs!L9)+0.5*Trade_Inputs!M9^2*Trade_Inputs!J9)/(Trade_Inputs!M9*SQRT(Trade_Inputs!J9)),"") | L9: =IF(F9="Linear",IF(E9="Long",1,-1),IF(AND(F9="Option",G9="Call"),IF(E9="Long",NORMSDIST(K9),-NORMSDIST(K9)),IF(AND(F9="Option",G9="Put"),IF(E9="Long",-NORMSDIST(-K9),NORMSDIST(-K9)),""))) | M9: =SQRT(MIN(MAX(H9,Supervisory_Params!$B$25/Supervisory_Params!$B$26),1)) | N9: =Supervisory_Params!$B$28 | O9: =L9*J9*M9 | P9: =L9*J9*N9 | Q9: =INDEX(Supervisory_Params!$D$5:$D$13,MATCH(C9&"|"&Trade_Inputs!O9,Supervisory_Params!$C$5:$C$13,0)) | R9: =IF(OR(C9="IR",C9="FX"),0,IF(C9="Commodity",Supervisory_Params!$B$23,IF(ISNUMBER(SEARCH("Index",Trade_Inputs!O9)),Supervisory_Params!$B$22,Supervisory_Params!$B$21)))
A10: =Trade_Inputs!A10 | B10: =Trade_Inputs!B10 | C10: =Trade_Inputs!C10 | D10: =Trade_Inputs!D10 | E10: =Trade_Inputs!E10 | F10: =Trade_Inputs!F10 | G10: =Trade_Inputs!G10 | H10: =Trade_Inputs!J10 | I10: =IF(OR(C10="IR",C10="Credit"),(EXP(-0.05*Trade_Inputs!I10)-EXP(-0.05*Trade_Inputs!J10))/0.05,"") | J10: =IF(OR(C10="IR",C10="Credit"),Trade_Inputs!H10*I10,Trade_Inputs!H10) | K10: =IF(F10="Option",(LN(Trade_Inputs!K10/Trade_Inputs!L10)+0.5*Trade_Inputs!M10^2*Trade_Inputs!J10)/(Trade_Inputs!M10*SQRT(Trade_Inputs!J10)),"") | L10: =IF(F10="Linear",IF(E10="Long",1,-1),IF(AND(F10="Option",G10="Call"),IF(E10="Long",NORMSDIST(K10),-NORMSDIST(K10)),IF(AND(F10="Option",G10="Put"),IF(E10="Long",-NORMSDIST(-K10),NORMSDIST(-K10)),""))) | M10: =SQRT(MIN(MAX(H10,Supervisory_Params!$B$25/Supervisory_Params!$B$26),1)) | N10: =Supervisory_Params!$B$28 | O10: =L10*J10*M10 | P10: =L10*J10*N10 | Q10: =INDEX(Supervisory_Params!$D$5:$D$13,MATCH(C10&"|"&Trade_Inputs!O10,Supervisory_Params!$C$5:$C$13,0)) | R10: =IF(OR(C10="IR",C10="FX"),0,IF(C10="Commodity",Supervisory_Params!$B$23,IF(ISNUMBER(SEARCH("Index",Trade_Inputs!O10)),Supervisory_Params!$B$22,Supervisory_Params!$B$21)))
A11: =Trade_Inputs!A11 | B11: =Trade_Inputs!B11 | C11: =Trade_Inputs!C11 | D11: =Trade_Inputs!D11 | E11: =Trade_Inputs!E11 | F11: =Trade_Inputs!F11 | G11: =Trade_Inputs!G11 | H11: =Trade_Inputs!J11 | I11: =IF(OR(C11="IR",C11="Credit"),(EXP(-0.05*Trade_Inputs!I11)-EXP(-0.05*Trade_Inputs!J11))/0.05,"") | J11: =IF(OR(C11="IR",C11="Credit"),Trade_Inputs!H11*I11,Trade_Inputs!H11) | K11: =IF(F11="Option",(LN(Trade_Inputs!K11/Trade_Inputs!L11)+0.5*Trade_Inputs!M11^2*Trade_Inputs!J11)/(Trade_Inputs!M11*SQRT(Trade_Inputs!J11)),"") | L11: =IF(F11="Linear",IF(E11="Long",1,-1),IF(AND(F11="Option",G11="Call"),IF(E11="Long",NORMSDIST(K11),-NORMSDIST(K11)),IF(AND(F11="Option",G11="Put"),IF(E11="Long",-NORMSDIST(-K11),NORMSDIST(-K11)),""))) | M11: =SQRT(MIN(MAX(H11,Supervisory_Params!$B$25/Supervisory_Params!$B$26),1)) | N11: =Supervisory_Params!$B$28 | O11: =L11*J11*M11 | P11: =L11*J11*N11 | Q11: =INDEX(Supervisory_Params!$D$5:$D$13,MATCH(C11&"|"&Trade_Inputs!O11,Supervisory_Params!$C$5:$C$13,0)) | R11: =IF(OR(C11="IR",C11="FX"),0,IF(C11="Commodity",Supervisory_Params!$B$23,IF(ISNUMBER(SEARCH("Index",Trade_Inputs!O11)),Supervisory_Params!$B$22,Supervisory_Params!$B$21)))
A12: =Trade_Inputs!A12 | B12: =Trade_Inputs!B12 | C12: =Trade_Inputs!C12 | D12: =Trade_Inputs!D12 | E12: =Trade_Inputs!E12 | F12: =Trade_Inputs!F12 | G12: =Trade_Inputs!G12 | H12: =Trade_Inputs!J12 | I12: =IF(OR(C12="IR",C12="Credit"),(EXP(-0.05*Trade_Inputs!I12)-EXP(-0.05*Trade_Inputs!J12))/0.05,"") | J12: =IF(OR(C12="IR",C12="Credit"),Trade_Inputs!H12*I12,Trade_Inputs!H12) | K12: =IF(F12="Option",(LN(Trade_Inputs!K12/Trade_Inputs!L12)+0.5*Trade_Inputs!M12^2*Trade_Inputs!J12)/(Trade_Inputs!M12*SQRT(Trade_Inputs!J12)),"") | L12: =IF(F12="Linear",IF(E12="Long",1,-1),IF(AND(F12="Option",G12="Call"),IF(E12="Long",NORMSDIST(K12),-NORMSDIST(K12)),IF(AND(F12="Option",G12="Put"),IF(E12="Long",-NORMSDIST(-K12),NORMSDIST(-K12)),""))) | M12: =SQRT(MIN(MAX(H12,Supervisory_Params!$B$25/Supervisory_Params!$B$26),1)) | N12: =Supervisory_Params!$B$28 | O12: =L12*J12*M12 | P12: =L12*J12*N12 | Q12: =INDEX(Supervisory_Params!$D$5:$D$13,MATCH(C12&"|"&Trade_Inputs!O12,Supervisory_Params!$C$5:$C$13,0)) | R12: =IF(OR(C12="IR",C12="FX"),0,IF(C12="Commodity",Supervisory_Params!$B$23,IF(ISNUMBER(SEARCH("Index",Trade_Inputs!O12)),Supervisory_Params!$B$22,Supervisory_Params!$B$21)))
A13: =Trade_Inputs!A13 | B13: =Trade_Inputs!B13 | C13: =Trade_Inputs!C13 | D13: =Trade_Inputs!D13 | E13: =Trade_Inputs!E13 | F13: =Trade_Inputs!F13 | G13: =Trade_Inputs!G13 | H13: =Trade_Inputs!J13 | I13: =IF(OR(C13="IR",C13="Credit"),(EXP(-0.05*Trade_Inputs!I13)-EXP(-0.05*Trade_Inputs!J13))/0.05,"") | J13: =IF(OR(C13="IR",C13="Credit"),Trade_Inputs!H13*I13,Trade_Inputs!H13) | K13: =IF(F13="Option",(LN(Trade_Inputs!K13/Trade_Inputs!L13)+0.5*Trade_Inputs!M13^2*Trade_Inputs!J13)/(Trade_Inputs!M13*SQRT(Trade_Inputs!J13)),"") | L13: =IF(F13="Linear",IF(E13="Long",1,-1),IF(AND(F13="Option",G13="Call"),IF(E13="Long",NORMSDIST(K13),-NORMSDIST(K13)),IF(AND(F13="Option",G13="Put"),IF(E13="Long",-NORMSDIST(-K13),NORMSDIST(-K13)),""))) | M13: =SQRT(MIN(MAX(H13,Supervisory_Params!$B$25/Supervisory_Params!$B$26),1)) | N13: =Supervisory_Params!$B$28 | O13: =L13*J13*M13 | P13: =L13*J13*N13 | Q13: =INDEX(Supervisory_Params!$D$5:$D$13,MATCH(C13&"|"&Trade_Inputs!O13,Supervisory_Params!$C$5:$C$13,0)) | R13: =IF(OR(C13="IR",C13="FX"),0,IF(C13="Commodity",Supervisory_Params!$B$23,IF(ISNUMBER(SEARCH("Index",Trade_Inputs!O13)),Supervisory_Params!$B$22,Supervisory_Params!$B$21)))
A14: =Trade_Inputs!A14 | B14: =Trade_Inputs!B14 | C14: =Trade_Inputs!C14 | D14: =Trade_Inputs!D14 | E14: =Trade_Inputs!E14 | F14: =Trade_Inputs!F14 | G14: =Trade_Inputs!G14 | H14: =Trade_Inputs!J14 | I14: =IF(OR(C14="IR",C14="Credit"),(EXP(-0.05*Trade_Inputs!I14)-EXP(-0.05*Trade_Inputs!J14))/0.05,"") | J14: =IF(OR(C14="IR",C14="Credit"),Trade_Inputs!H14*I14,Trade_Inputs!H14) | K14: =IF(F14="Option",(LN(Trade_Inputs!K14/Trade_Inputs!L14)+0.5*Trade_Inputs!M14^2*Trade_Inputs!J14)/(Trade_Inputs!M14*SQRT(Trade_Inputs!J14)),"") | L14: =IF(F14="Linear",IF(E14="Long",1,-1),IF(AND(F14="Option",G14="Call"),IF(E14="Long",NORMSDIST(K14),-NORMSDIST(K14)),IF(AND(F14="Option",G14="Put"),IF(E14="Long",-NORMSDIST(-K14),NORMSDIST(-K14)),""))) | M14: =SQRT(MIN(MAX(H14,Supervisory_Params!$B$25/Supervisory_Params!$B$26),1)) | N14: =Supervisory_Params!$B$28 | O14: =L14*J14*M14 | P14: =L14*J14*N14 | Q14: =INDEX(Supervisory_Params!$D$5:$D$13,MATCH(C14&"|"&Trade_Inputs!O14,Supervisory_Params!$C$5:$C$13,0)) | R14: =IF(OR(C14="IR",C14="FX"),0,IF(C14="Commodity",Supervisory_Params!$B$23,IF(ISNUMBER(SEARCH("Index",Trade_Inputs!O14)),Supervisory_Params!$B$22,Supervisory_Params!$B$21)))
A15: =Trade_Inputs!A15 | B15: =Trade_Inputs!B15 | C15: =Trade_Inputs!C15 | D15: =Trade_Inputs!D15 | E15: =Trade_Inputs!E15 | F15: =Trade_Inputs!F15 | G15: =Trade_Inputs!G15 | H15: =Trade_Inputs!J15 | I15: =IF(OR(C15="IR",C15="Credit"),(EXP(-0.05*Trade_Inputs!I15)-EXP(-0.05*Trade_Inputs!J15))/0.05,"") | J15: =IF(OR(C15="IR",C15="Credit"),Trade_Inputs!H15*I15,Trade_Inputs!H15) | K15: =IF(F15="Option",(LN(Trade_Inputs!K15/Trade_Inputs!L15)+0.5*Trade_Inputs!M15^2*Trade_Inputs!J15)/(Trade_Inputs!M15*SQRT(Trade_Inputs!J15)),"") | L15: =IF(F15="Linear",IF(E15="Long",1,-1),IF(AND(F15="Option",G15="Call"),IF(E15="Long",NORMSDIST(K15),-NORMSDIST(K15)),IF(AND(F15="Option",G15="Put"),IF(E15="Long",-NORMSDIST(-K15),NORMSDIST(-K15)),""))) | M15: =SQRT(MIN(MAX(H15,Supervisory_Params!$B$25/Supervisory_Params!$B$26),1)) | N15: =Supervisory_Params!$B$28 | O15: =L15*J15*M15 | P15: =L15*J15*N15 | Q15: =INDEX(Supervisory_Params!$D$5:$D$13,MATCH(C15&"|"&Trade_Inputs!O15,Supervisory_Params!$C$5:$C$13,0)) | R15: =IF(OR(C15="IR",C15="FX"),0,IF(C15="Commodity",Supervisory_Params!$B$23,IF(ISNUMBER(SEARCH("Index",Trade_Inputs!O15)),Supervisory_Params!$B$22,Supervisory_Params!$B$21)))
... A21: =Trade_Inputs!A21 | B21: =Trade_Inputs!B21 | C21: =Trade_Inputs!C21 | D21: =Trade_Inputs!D21 | E21: =Trade_Inputs!E21 | F21: =Trade_Inputs!F21 | G21: =Trade_Inputs!G21 | H21: =Trade_Inputs!J21 | I21: =IF(OR(C21="IR",C21="Credit"),(EXP(-0.05*Trade_Inputs!I21)-EXP(-0.05*Trade_Inputs!J21))/0.05,"") | J21: =IF(OR(C21="IR",C21="Credit"),Trade_Inputs!H21*I21,Trade_Inputs!H21) | K21: =IF(F21="Option",(LN(Trade_Inputs!K21/Trade_Inputs!L21)+0.5*Trade_Inputs!M21^2*Trade_Inputs!J21)/(Trade_Inputs!M21*SQRT(Trade_Inputs!J21)),"") | L21: =IF(F21="Linear",IF(E21="Long",1,-1),IF(AND(F21="Option",G21="Call"),IF(E21="Long",NORMSDIST(K21),-NORMSDIST(K21)),IF(AND(F21="Option",G21="Put"),IF(E21="Long",-NORMSDIST(-K21),NORMSDIST(-K21)),""))) | M21: =SQRT(MIN(MAX(H21,Supervisory_Params!$B$25/Supervisory_Params!$B$26),1)) | N21: =Supervisory_Params!$B$28 | O21: =L21*J21*M21 | P21: =L21*J21*N21 | Q21: =INDEX(Supervisory_Params!$D$5:$D$13,MATCH(C21&"|"&Trade_Inputs!O21,Supervisory_Params!$C$5:$C$13,0)) | R21: =IF(OR(C21="IR",C21="FX"),0,IF(C21="Commodity",Supervisory_Params!$B$23,IF(ISNUMBER(SEARCH("Index",Trade_Inputs!O21)),Supervisory_Params!$B$22,Supervisory_Params!$B$21)))

Sheet AddOn_Aggregation
A1: AddOn Aggregation, RC, PFE & EAD - 4 scenarios (actual vs. hypothetical opposite-margin-status)
A3: SCENARIO 1: Netting Set A (CORP-001) - ACTUAL: Unmargined
A4: V - net MTM of netting set | B4: =SUMIF(Calc_Engine!$B$4:$B$21,"NS-A",Trade_Inputs!$N$4:$N$21)
A5: C - haircut value of net collateral held | B5: 0
A6: TH - threshold (n/a, unmargined) | B6: 0
A7: MTA - minimum transfer amount (n/a, unmargined) | B7: 0
A8: NICA - net independent collateral amount | B8: 0
A9: IR AddOn (3 maturity buckets, cross-bucket correlation)
A10: Currency | B10: Bucket1 (<1y) | C10: Bucket2 (1-5y) | D10: Bucket3 (>5y) | E10: Eff. D (HS) | F10: AddOn
A11: USD | B11: =SUMPRODUCT((Calc_Engine!$B$4:$B$21="NS-A")*(Calc_Engine!$C$4:$C$21="IR")*(Calc_Engine!$D$4:$D$21="USD")*(Calc_Engine!$H$4:$H$21<1)*Calc_Engine!$O$4:$O$21) | C11: =SUMPRODUCT((Calc_Engine!$B$4:$B$21="NS-A")*(Calc_Engine!$C$4:$C$21="IR")*(Calc_Engine!$D$4:$D$21="USD")*(Calc_Engine!$H$4:$H$21>=1)*(Calc_Engine!$H$4:$H$21<=5)*Calc_Engine!$O$4:$O$21) | D11: =SUMPRODUCT((Calc_Engine!$B$4:$B$21="NS-A")*(Calc_Engine!$C$4:$C$21="IR")*(Calc_Engine!$D$4:$D$21="USD")*(Calc_Engine!$H$4:$H$21>5)*Calc_Engine!$O$4:$O$21) | E11: =SQRT(B11^2+C11^2+D11^2+1.4*B11*C11+1.4*C11*D11+0.6*B11*D11) | F11: =INDEX(Supervisory_Params!$D$5:$D$13,MATCH("IR|NA",Supervisory_Params!$C$5:$C$13,0))*E11
A12: EUR | B12: =SUMPRODUCT((Calc_Engine!$B$4:$B$21="NS-A")*(Calc_Engine!$C$4:$C$21="IR")*(Calc_Engine!$D$4:$D$21="EUR")*(Calc_Engine!$H$4:$H$21<1)*Calc_Engine!$O$4:$O$21) | C12: =SUMPRODUCT((Calc_Engine!$B$4:$B$21="NS-A")*(Calc_Engine!$C$4:$C$21="IR")*(Calc_Engine!$D$4:$D$21="EUR")*(Calc_Engine!$H$4:$H$21>=1)*(Calc_Engine!$H$4:$H$21<=5)*Calc_Engine!$O$4:$O$21) | D12: =SUMPRODUCT((Calc_Engine!$B$4:$B$21="NS-A")*(Calc_Engine!$C$4:$C$21="IR")*(Calc_Engine!$D$4:$D$21="EUR")*(Calc_Engine!$H$4:$H$21>5)*Calc_Engine!$O$4:$O$21) | E12: =SQRT(B12^2+C12^2+D12^2+1.4*B12*C12+1.4*C12*D12+0.6*B12*D12) | F12: =INDEX(Supervisory_Params!$D$5:$D$13,MATCH("IR|NA",Supervisory_Params!$C$5:$C$13,0))*E12
A13: AddOn (IR total, all currencies) | B13: =$F$11+$F$12
A14: FX AddOn (sum by currency pair hedging set)
A15: AddOn (EURUSD) | B15: =ABS(SUMPRODUCT((Calc_Engine!$B$4:$B$21="NS-A")*(Calc_Engine!$C$4:$C$21="FX")*(Calc_Engine!$D$4:$D$21="EURUSD")*Calc_Engine!$O$4:$O$21))*INDEX(Supervisory_Params!$D$5:$D$13,MATCH("FX|NA",Supervisory_Params!$C$5:$C$13,0))
A16: AddOn (GBPUSD) | B16: =ABS(SUMPRODUCT((Calc_Engine!$B$4:$B$21="NS-A")*(Calc_Engine!$C$4:$C$21="FX")*(Calc_Engine!$D$4:$D$21="GBPUSD")*Calc_Engine!$O$4:$O$21))*INDEX(Supervisory_Params!$D$5:$D$13,MATCH("FX|NA",Supervisory_Params!$C$5:$C$13,0))
A17: AddOn (USDJPY) | B17: =ABS(SUMPRODUCT((Calc_Engine!$B$4:$B$21="NS-A")*(Calc_Engine!$C$4:$C$21="FX")*(Calc_Engine!$D$4:$D$21="USDJPY")*Calc_Engine!$O$4:$O$21))*INDEX(Supervisory_Params!$D$5:$D$13,MATCH("FX|NA",Supervisory_Params!$C$5:$C$13,0))
A18: AddOn (FX total, all pairs) | B18: =$B$15+$B$16+$B$17
A19: Credit
A20: Sum(rho x SF x EffNotional) | B20: =SUMPRODUCT((Calc_Engine!$B$4:$B$21="NS-A")*(Calc_Engine!$C$4:$C$21="Credit")*Calc_Engine!$R$4:$R$21*Calc_Engine!$Q$4:$Q$21*Calc_Engine!$O$4:$O$21)
A21: Sum((1-rho^2) x (SF x EffNotional)^2) | B21: =SUMPRODUCT((Calc_Engine!$B$4:$B$21="NS-A")*(Calc_Engine!$C$4:$C$21="Credit")*(1-Calc_Engine!$R$4:$R$21^2)*(Calc_Engine!$Q$4:$Q$21*Calc_Engine!$O$4:$O$21)^2)
A22: AddOn (Credit) | B22: =SQRT($B$20^2+$B$21)
A23: Equity
A24: Sum(rho x SF x EffNotional) | B24: =SUMPRODUCT((Calc_Engine!$B$4:$B$21="NS-A")*(Calc_Engine!$C$4:$C$21="Equity")*Calc_Engine!$R$4:$R$21*Calc_Engine!$Q$4:$Q$21*Calc_Engine!$O$4:$O$21)
A25: Sum((1-rho^2) x (SF x EffNotional)^2) | B25: =SUMPRODUCT((Calc_Engine!$B$4:$B$21="NS-A")*(Calc_Engine!$C$4:$C$21="Equity")*(1-Calc_Engine!$R$4:$R$21^2)*(Calc_Engine!$Q$4:$Q$21*Calc_Engine!$O$4:$O$21)^2)
A26: AddOn (Equity) | B26: =SQRT($B$24^2+$B$25)
A27: Commodity
A28: Sum(rho x SF x EffNotional) | B28: =SUMPRODUCT((Calc_Engine!$B$4:$B$21="NS-A")*(Calc_Engine!$C$4:$C$21="Commodity")*Calc_Engine!$R$4:$R$21*Calc_Engine!$Q$4:$Q$21*Calc_Engine!$O$4:$O$21)
A29: Sum((1-rho^2) x (SF x EffNotional)^2) | B29: =SUMPRODUCT((Calc_Engine!$B$4:$B$21="NS-A")*(Calc_Engine!$C$4:$C$21="Commodity")*(1-Calc_Engine!$R$4:$R$21^2)*(Calc_Engine!$Q$4:$Q$21*Calc_Engine!$O$4:$O$21)^2)
A30: AddOn (Commodity) | B30: =SQRT($B$28^2+$B$29)
A31: AddOn aggregate (all asset classes) | B31: =$B$13+$B$18+$B$22+$B$26+$B$30
A32: Multiplier | B32: =IF($B$31=0,1,MIN(1,Supervisory_Params!$B$18+(1-Supervisory_Params!$B$18)*EXP(($B$4-$B$5)/(2*(1-Supervisory_Params!$B$18)*$B$31))))
A33: PFE | B33: =$B$32*$B$31
A34: RC (Replacement Cost) | B34: =MAX($B$4-$B$5,0)
A35: EAD = alpha x (RC + PFE) | B35: =Supervisory_Params!$B$17*($B$34+$B$33)
A37: SCENARIO 2: Netting Set A (CORP-001) - HYPOTHETICAL: Same trades, if margined
A38: V - net MTM of netting set | B38: =SUMIF(Calc_Engine!$B$4:$B$21,"NS-A",Trade_Inputs!$N$4:$N$21)
A39: C - haircut value of net collateral held | B39: 0
A40: TH - threshold | B40: 0
A41: MTA - minimum transfer amount | B41: 250000
A42: NICA - net independent collateral amount | B42: 0
...

Sheet Summary
A1: Summary - EAD Comparison
A3: Netting Set | B3: Margin Status | C3: RC ($) | D3: PFE ($) | E3: EAD ($)
A4: Netting Set A (CORP-001) | B4: Actual - Unmargined | C4: =AddOn_Aggregation!$B$34 | D4: =AddOn_Aggregation!$B$33 | E4: =AddOn_Aggregation!$B$35
A5: Netting Set A (CORP-001) | B5: Hypothetical - Margined | C5: =AddOn_Aggregation!$B$68 | D5: =AddOn_Aggregation!$B$67 | E5: =AddOn_Aggregation!$B$69
A6: Netting Set B (BANK-001) | B6: Actual - Margined | C6: =AddOn_Aggregation!$B$96 | D6: =AddOn_Aggregation!$B$95 | E6: =AddOn_Aggregation!$B$97
A7: Netting Set B (BANK-001) | B7: Hypothetical - Unmargined | C7: =AddOn_Aggregation!$B$124 | D7: =AddOn_Aggregation!$B$123 | E7: =AddOn_Aggregation!$B$125
A9: Margining impact - Netting Set A | E9: =E5-E4
A10: Margining impact - Netting Set B | E10: =E7-E6

Sheet BACVA_Params
A1: BA-CVA Supervisory Parameters (Reduced BA-CVA, editable blue cells)
A3: Regulatory Constants
A4: Parameter | B4: Value | C4: Note
A5: Alpha (same supervisory constant as SA-CCR EAD) | B5: 1.4
A6: Rho (correlation between counterparties) | B6: 0.5
A7: Discount scalar DS_BA-CVA | B7: 0.65
A9: Risk Weights (RW) by sector x credit quality
A10: Sector | B10: Credit Quality | C10: Key | D10: RW | E10: Note
A11: Sovereigns_CentralBanks | B11: IG | C11: =A11&"|"&B11 | D11: 0.005
A12: Sovereigns_CentralBanks | B12: HY_NR | C12: =A12&"|"&B12 | D12: 0.02
A13: LocalGovernment_Education | B13: IG | C13: =A13&"|"&B13 | D13: 0.01
A14: LocalGovernment_Education | B14: HY_NR | C14: =A14&"|"&B14 | D14: 0.04
A15: Financials | B15: IG | C15: =A15&"|"&B15 | D15: 0.05
A16: Financials | B16: HY_NR | C16: =A16&"|"&B16 | D16: 0.12
A17: BasicMaterials_Energy_Industrials | B17: IG | C17: =A17&"|"&B17 | D17: 0.03
A18: BasicMaterials_Energy_Industrials | B18: HY_NR | C18: =A18&"|"&B18 | D18: 0.07
A19: ConsumerGoods_Transportation | B19: IG | C19: =A19&"|"&B19 | D19: 0.03
A20: ConsumerGoods_Transportation | B20: HY_NR | C20: =A20&"|"&B20 | D20: 0.085
A21: Technology_Telecom | B21: IG | C21: =A21&"|"&B21 | D21: 0.02
A22: Technology_Telecom | B22: HY_NR | C22: =A22&"|"&B22 | D22: 0.055
... A26: Other | B26: HY_NR | C26: =A26&"|"&B26 | D26: 0.12

Sheet BACVA_Counterparties
A1: BA-CVA Counterparty Assignment (illustrative, editable blue cells)
A3: Not part of the original SA-CCR sample data (trade-level notional/maturity/MTM only). Sector and credit quality assigned here for BA-CVA risk-weight lookup; illustrative, same as the rest of the sample portfolio's notionals, MTMs, and CSA terms.
A5: Netting Set | B5: Counterparty | C5: Sector | D5: Credit Quality
A6: NS-A | B6: CORP-001 | C6: BasicMaterials_Energy_Industrials | D6: IG
A7: NS-B | B7: BANK-001 | C7: Financials | D7: IG

Sheet BACVA_Calc
A1: BA-CVA Per-Counterparty SCVA (green = link to other sheets, black = formula)
A3: Netting Set | B3: Counterparty | C3: Sector | D3: Credit Quality | E3: EAD_NS ($) | F3: M_NS (yrs, notional-wtd avg) | G3: DF_NS | H3: RW_c | I3: SCVA_c ($)
A4: =BACVA_Counterparties!A6 | B4: =BACVA_Counterparties!B6 | C4: =BACVA_Counterparties!C6 | D4: =BACVA_Counterparties!D6 | E4: =IF(BACVA_Counterparties!A6="NS-A",Summary!$E$4,Summary!$E$6) | F4: =SUMPRODUCT((Trade_Inputs!$B$4:$B$21=BACVA_Counterparties!A6)*Trade_Inputs!$H$4:$H$21*Trade_Inputs!$J$4:$J$21)/SUMIF(Trade_Inputs!$B$4:$B$21,BACVA_Counterparties!A6,Trade_Inputs!$H$4:$H$21) | G4: =(1-EXP(-0.05*F4))/(0.05*F4) | H4: =INDEX(BACVA_Params!$D$11:$D$26,MATCH(C4&"|"&D4,BACVA_Params!$C$11:$C$26,0)) | I4: =(1/BACVA_Params!$B$5)*H4*(F4*E4*G4)
A5: =BACVA_Counterparties!A7 | B5: =BACVA_Counterparties!B7 | C5: =BACVA_Counterparties!C7 | D5: =BACVA_Counterparties!D7 | E5: =IF(BACVA_Counterparties!A7="NS-A",Summary!$E$4,Summary!$E$6) | F5: =SUMPRODUCT((Trade_Inputs!$B$4:$B$21=BACVA_Counterparties!A7)*Trade_Inputs!$H$4:$H$21*Trade_Inputs!$J$4:$J$21)/SUMIF(Trade_Inputs!$B$4:$B$21,BACVA_Counterparties!A7,Trade_Inputs!$H$4:$H$21) | G5: =(1-EXP(-0.05*F5))/(0.05*F5) | H5: =INDEX(BACVA_Params!$D$11:$D$26,MATCH(C5&"|"&D5,BACVA_Params!$C$11:$C$26,0)) | I5: =(1/BACVA_Params!$B$5)*H5*(F5*E5*G5)

Sheet BACVA_Summary
A1: BA-CVA Capital Charge Summary
A3: SCVA by counterparty
A4: Counterparty | B4: SCVA ($)
A5: =BACVA_Calc!B4 | B5: =BACVA_Calc!I4
A6: =BACVA_Calc!B5 | B6: =BACVA_Calc!I5
A8: Sum(SCVA_c) | B8: =SUM(B5:B6)
A9: Sum(SCVA_c^2) | B9: =SUMSQ(B5:B6)
A10: K_reduced | B10: =SQRT((BACVA_Params!$B$6*B8)^2+(1-BACVA_Params!$B$6^2)*B9)
A11: BA-CVA capital charge (DS x K_reduced) | B11: =BACVA_Params!$B$7*B10
